2024-10-13 20:34:31,745 - INFO - C:\Users\victo\Desktop\DESENVOVLIMENTE\desenvovlimento_sage_1\cadastro\views.py changed, reloading.
2024-10-13 20:35:03,791 - ERROR - Internal Server Error: /cadastro/
Traceback (most recent call last):
  File "C:\Users\victo\Desktop\DESENVOVLIMENTE\desenvovlimento_sage_1\venv\Lib\site-packages\django\core\handlers\exception.py", line 55, in inner
    response = get_response(request)
               ^^^^^^^^^^^^^^^^^^^^^
  File "C:\Users\victo\Desktop\DESENVOVLIMENTE\desenvovlimento_sage_1\venv\Lib\site-packages\django\core\handlers\base.py", line 197, in _get_response
    response = wrapped_callback(request, *callback_args, **callback_kwargs)
               ^^^^^^^^^^^^^^^^^^^^^^^^^^^^^^^^^^^^^^^^^^^^^^^^^^^^^^^^^^^^
  File "C:\Users\victo\Desktop\DESENVOVLIMENTE\desenvovlimento_sage_1\cadastro\views.py", line 17, in cadastro
    logging.debug('Dados do formulário: %s', form.cleaned_data)  #
                                            ^^^^
UnboundLocalError: cannot access local variable 'form' where it is not associated with a value
2024-10-13 20:36:12,507 - INFO - C:\Users\victo\Desktop\DESENVOVLIMENTE\desenvovlimento_sage_1\cadastro\views.py changed, reloading.
2024-10-13 20:36:17,707 - DEBUG - Dados do formulário: {'nome': 'victor_123', 'email': 'saaa@gmail.com', 'data_de_nascimento': datetime.date(2003, 8, 7), 'cpf': '12345', 'password': '123'}
2024-10-13 20:38:26,834 - INFO - C:\Users\victo\Desktop\DESENVOVLIMENTE\desenvovlimento_sage_1\cadastro\views.py changed, reloading.
2024-10-13 20:38:30,092 - INFO - C:\Users\victo\Desktop\DESENVOVLIMENTE\desenvovlimento_sage_1\cadastro\views.py changed, reloading.
2024-10-13 20:42:04,956 - INFO - C:\Users\victo\Desktop\DESENVOVLIMENTE\desenvovlimento_sage_1\cadastro\views.py changed, reloading.
